<?xml version="1.0" ?>
<!-- =================================================================================== -->
<!-- |    This document was autogenerated by xacro from llb_car.xacro                  | -->
<!-- |    EDITING THIS FILE BY HAND IS NOT RECOMMENDED                                 | -->
<!-- =================================================================================== -->
<robot name="llb_car" xmlns:controller="http://playerstage.sourceforge.net/gazebo/xmlschema/#controller" xmlns:interface="http://playerstage.sourceforge.net/gazebo/xmlschema/#interface" xmlns:sensor="http://playerstage.sourceforge.net/gazebo/xmlschema/#sensor" xmlns:xacro="http://playerstage.sourceforge.net/gazebo/xmlschema/#interface">
  <link name="wheel1">
    <visual>
      <geometry>
        <cylinder length="0.055" radius="0.0575"/>
      </geometry>
      <material name="black">
        <color rgba="0 0 0 1"/>
      </material>
    </visual>
  </link>
  <joint name="joint_base_wheel1" type="revolute">
    <axis xyz="0 0 1" />
    <parent link="base_link"/>
    <child link="wheel1"/>
    <origin rpy="1.57 0 0" xyz="0.05 0.0975 0.0"/>
    <limit effort="100" velocity="100" lower="-1.5707963" upper="1.5707963" />
	<joint_properties damping="0.0" friction="0.0" />
</joint>
 <link name="wheel2">
    <visual>
      <geometry>
        <cylinder length="0.055" radius="0.0575"/>
      </geometry>
      <material name="black">
        <color rgba="0 0 0 1"/>
      </material>
    </visual>
  </link>
  <joint name="joint_base_wheel2" type="revolute">
  	<axis xyz="0 0 1" />
    <parent link="base_link"/>
    <child link="wheel2"/>
     <origin rpy="1.57 0 0" xyz="0.05 -0.0975 0.0"/>
    <limit effort="100" velocity="100" lower="-1.5707963" upper="1.5707963" />
	<joint_properties damping="0.0" friction="0.0" />
</joint>
  <link name="base_link">
    <visual>
      <geometry>
        <box size=".2 .12 .11"/>
      </geometry>
      <origin rpy="0 0 0" xyz="0 0 0.0575"/>
      <material name="white">
        <color rgba="1 1 1 1"/>
      </material>
    </visual>
  </link>
  <joint name="base_laser_bottom_joint" type="fixed">
    <origin rpy="0 0 0 " xyz="0.0 0.0 0.1305"/>
    <parent link="base_link"/>
    <child link="base_laser_bottom"/>
  </joint>
  <link name="base_laser_bottom">
    <visual>
      <origin rpy="0 0 0" xyz="0 0 0"/>
      <geometry>
        <box size="0.05 0.05 0.041"/>
      </geometry>
      <material name="DarkGrey"/>
    </visual>
    <collision>
      <origin rpy="0 0 0" xyz="0 0 0"/>
      <geometry>
        <box size="0.05 0.05 0.041"/>
      </geometry>
    </collision>
    <inertial>
      <inertia ixx="0.001" ixy="0" ixz="0" iyy="0.001" iyz="0" izz="0.001"/>
      <mass value="0.1"/>
    </inertial>
  </link>
  <link name="base_laser_middle">
    <visual>
      <origin rpy="0 0 0" xyz="0 0 0"/>
      <geometry>
        <cylinder length="0.0115" radius=".02"/>
      </geometry>
      <material name="dark_grey">
        <color rgba="0.2 0.2 0.2 1.0"/>
      </material>
    </visual>
    <collision>
      <origin rpy="0 0 0" xyz="0 0 0"/>
      <geometry>
        <cylinder length="0.0115" radius=".02"/>
      </geometry>
    </collision>
    <inertial>
      <inertia ixx="0.001" ixy="0" ixz="0" iyy="0.001" iyz="0" izz="0.001"/>
      <mass value="0.1"/>
    </inertial>
  </link>
  <joint name="base_laser_middle_joint" type="fixed">
    <parent link="base_laser_bottom"/>
    <child link="base_laser_middle"/>
    <origin rpy="0 0 0" xyz="0 0 0.02625"/>
  </joint>
  <link name="laser">
    <visual>
      <origin rpy="0 0 0" xyz="0 0 0"/>
      <geometry>
        <cylinder length="0.0175" radius=".0185"/>
      </geometry>
      <material name="red">
        <color rgba="0.8 0.1 0.1 1.0"/>
      </material>
    </visual>
    <collision>
      <origin rpy="0 0 0" xyz="0 0 0"/>
      <geometry>
        <cylinder length="0.0175" radius=".0185"/>
      </geometry>
    </collision>
    <inertial>
      <inertia ixx="0.001" ixy="0" ixz="0" iyy="0.001" iyz="0" izz="0.001"/>
      <mass value="0.1"/>
    </inertial>
  </link>
  <joint name="base_laser_joint" type="fixed">
    <parent link="base_laser_middle"/>
    <child link="laser"/>
    <origin rpy="0 0 0" xyz="0 0 0.0145"/>
  </joint>
  <link name="camera_link">
    <visual>
      <geometry>
        <box size="0.02 .08 .02"/>
      </geometry>
      <material name="blue">
        <color rgba="0 0 255 1"/>
      </material>
    </visual>
  </link>
  <joint name="camera_link_to_base_link" type="fixed">
    <parent link="base_link"/>
    <child link="camera_link"/>
    <origin rpy="0 0 0" xyz="0.04 0.0 0.12"/>
  </joint>
  <link name="camera_depth_frame">
    <visual>
      <geometry>
        <box size="0.005 .005 .005"/>
      </geometry>
      <material name="blue">
        <color rgba="0 0 255 1"/>
      </material>
    </visual>
  </link>
  <joint name="camera_depth_joint" type="fixed">
    <origin rpy="0 0 0" xyz="0 0 0.01"/>
    <parent link="camera_link"/>
    <child link="camera_depth_frame"/>
  </joint>
  <link name="camera_depth_optical_frame">
    <visual>
      <geometry>
        <box size="0.005 .005 .005"/>
      </geometry>
      <material name="blue">
        <color rgba="0 0 255 1"/>
      </material>
    </visual>
  </link>
  <joint name="depth_optical_joint" type="fixed">
    <origin rpy="-1.57 0 -1.57" xyz="0 0 0"/>
    <parent link="camera_depth_frame"/>
    <child link="camera_depth_optical_frame"/>
  </joint>
</robot>

