<?xml version="1.0"?>
<robot name="llb">
  <link name="base_link">
    <visual>
      <geometry>
        <box size="0.20 .15 .003"/>
      </geometry>
    </visual>
  </link>
  <link name="arm_base">
    <visual>
      <geometry>
       <box size="0.11 .11 .013"/>
      </geometry>
      <material name="black">
          <color rgba="255 255 255 1"/>
      </material>  
    </visual>
  </link>  
  
  <joint name="base_to_arm_base" type="fixed">
    <parent link="base_link"/>
    <child link="arm_base"/>
    <origin xyz="0.085 0.0 0.008"/>
  </joint>  
  
<!--arm-->
  <link name="arm_round_joint_stevo0">
    <visual>
      <geometry>
       <cylinder length=".013" radius="0.05"></cylinder>
      </geometry>
      <material name="blue">
          <color rgba="0 0 255 1"/>
      </material>  
    </visual>
  </link>
  
  <joint name="arm_base_to_arm_round_joint_stevo0" type="revolute">
    <axis xyz="0 0 1"/> 
    <parent link="arm_base"/>
    <child link="arm_round_joint_stevo0"/>
    <origin rpy="0 0 0" xyz="0.00 0.00 0.013"/>
    <limit effort="100" velocity="100" lower="-1.5707963" upper="1.5707963"/> 
    <joint_properties damping="0.0" friction="0.0"/>
  </joint>  
  
  <link name="shoulder_1">
    <visual>
      <geometry>
       <box size="0.065 .065 .037"/>
      </geometry>
      <material name="silver1">
          <color rgba="232 232 232 1"/>
      </material>  
    </visual>
  </link>  
  
  <joint name="arm_round_joint_stevo0_to_shoulder_1" type="fixed">
    <parent link="arm_round_joint_stevo0"/>
    <child link="shoulder_1"/>
    <origin xyz="0.0 0.0 0.025"/>
  </joint>  
  
   <link name="shoulder_2">
    <visual>
      <geometry>
       <box size="0.05 .065 .105"/>
      </geometry>
      <material name="silver">
          <color rgba="232 232 232 1"/>
      </material>  
    </visual>
  </link>  
  
  <joint name="shoulder_1_to_shoulder_1" type="fixed">
    <parent link="shoulder_1"/>
    <child link="shoulder_2"/>
    <origin rpy="0 0.785398 0" xyz="0.022 0.0 0.03915"/>
  </joint>  
  
  <link name="arm_joint_stevo1">
    <visual>
      <geometry>
       <cylinder length=".09" radius="0.025"></cylinder>
      </geometry>
      <material name="black">
          <color rgba="255 255 255 1"/>
      </material>  
    </visual>
  </link>
  
  <joint name="shoulder_2_to_arm_joint_stevo1" type="revolute">
    <axis xyz="0 0 1"/> 
    <parent link="shoulder_2"/>
    <child link="arm_joint_stevo1"/>
    <origin rpy="1.5707963 0 0" xyz="0.00 0.00 0.025"/>
    <limit effort="100" velocity="100" lower="-0.1899" upper="1.5707963"/> 
    <joint_properties damping="0.0" friction="0.0"/>
  </joint>  
  
   <link name="big_arm">
    <visual>
      <geometry>
       <box size="0.05 .05 .13"/>
      </geometry>
      <material name="blue">
          <color rgba="0 0 255 1"/>
      </material>  
    </visual>
  </link>  
  
  <joint name="arm_joint_stevo1_to_big_arm" type="fixed">
    <parent link="arm_joint_stevo1"/>
    <child link="big_arm"/>
    <origin rpy="1.5707963 0 0" xyz="0.0 0.065 0.0"/>
  </joint>  
  
  <link name="arm_joint_stevo2">
    <visual>
      <geometry>
       <cylinder length=".06" radius="0.025"></cylinder>
      </geometry>
      <material name="black">
          <color rgba="255 255 255 1"/>
      </material>  
    </visual>
  </link>
  
  <joint name="big_arm_round_to_joint_stevo2" type="revolute">
    <axis xyz="0 0 1"/> 
    <parent link="big_arm"/>
    <child link="arm_joint_stevo2"/>
    <origin rpy="1.5707963 0 0" xyz="0.00 0.00 -0.065"/>
    <limit effort="100" velocity="100" lower="1.0" upper="2.5891"/> 
    <joint_properties damping="0.0" friction="0.0"/>
  </joint>    

  <link name="arm_joint_stevo3">
    <visual>
      <geometry>
       <cylinder length=".22" radius="0.012"></cylinder>
      </geometry>
      <material name="blue">
          <color rgba="0 0 255 1"/>
      </material>  
    </visual>
  </link>  
  
 <joint name="arm_joint_stevo2_to_arm_joint_stevo3" type="fixed">
    <axis xyz="0 0 1"/> 
    <parent link="arm_joint_stevo2"/>
    <child link="arm_joint_stevo3"/>
    <origin rpy="1.5707963 -0.52359877 0" xyz="0.00 -0.06 0.00"/>
  </joint> 

  <link name="wrist">
    <visual>
      <geometry>
       <box size="0.045 .04 .06"/>
      </geometry>
      <material name="blue">
          <color rgba="0 0 255 1"/>
      </material>  
    </visual>
  </link>  
  
  <joint name="arm_joint_stevo3_to_wrist" type="fixed">
    <parent link="arm_joint_stevo3"/>
    <child link="wrist"/>
    <origin rpy="0 0 0" xyz="0.0 0.0 0.09"/>
  </joint>  


 
 </robot>
